2020-04-24 17:30:04,803 INFO: Microblog startup [in /Users/andrew.xia/Documents/Github/flasky/app/__init__.py:45]
2020-04-24 17:46:17,731 INFO: Microblog startup [in /Users/andrew.xia/Documents/Github/flasky/app/__init__.py:45]
2020-04-24 18:00:29,079 INFO: Microblog startup [in /Users/andrew.xia/Documents/Github/flasky/app/__init__.py:45]
2020-04-24 18:01:57,334 ERROR: Exception on /edit_profile [POST] [in /Users/andrew.xia/Documents/Github/flasky/venv/lib/python3.6/site-packages/flask/app.py:1891]
Traceback (most recent call last):
  File "/Users/andrew.xia/Documents/Github/flasky/venv/lib/python3.6/site-packages/sqlalchemy/engine/base.py", line 1248, in _execute_context
    cursor, statement, parameters, context
  File "/Users/andrew.xia/Documents/Github/flasky/venv/lib/python3.6/site-packages/sqlalchemy/engine/default.py", line 590, in do_execute
    cursor.execute(statement, parameters)
sqlite3.IntegrityError: UNIQUE constraint failed: user.username

The above exception was the direct cause of the following exception:

Traceback (most recent call last):
  File "/Users/andrew.xia/Documents/Github/flasky/venv/lib/python3.6/site-packages/flask/app.py", line 2446, in wsgi_app
    response = self.full_dispatch_request()
  File "/Users/andrew.xia/Documents/Github/flasky/venv/lib/python3.6/site-packages/flask/app.py", line 1951, in full_dispatch_request
    rv = self.handle_user_exception(e)
  File "/Users/andrew.xia/Documents/Github/flasky/venv/lib/python3.6/site-packages/flask/app.py", line 1820, in handle_user_exception
    reraise(exc_type, exc_value, tb)
  File "/Users/andrew.xia/Documents/Github/flasky/venv/lib/python3.6/site-packages/flask/_compat.py", line 39, in reraise
    raise value
  File "/Users/andrew.xia/Documents/Github/flasky/venv/lib/python3.6/site-packages/flask/app.py", line 1949, in full_dispatch_request
    rv = self.dispatch_request()
  File "/Users/andrew.xia/Documents/Github/flasky/venv/lib/python3.6/site-packages/flask/app.py", line 1935, in dispatch_request
    return self.view_functions[rule.endpoint](**req.view_args)
  File "/Users/andrew.xia/Documents/Github/flasky/venv/lib/python3.6/site-packages/flask_login/utils.py", line 272, in decorated_view
    return func(*args, **kwargs)
  File "/Users/andrew.xia/Documents/Github/flasky/app/routes.py", line 88, in edit_profile
    db.session.commit()
  File "/Users/andrew.xia/Documents/Github/flasky/venv/lib/python3.6/site-packages/sqlalchemy/orm/scoping.py", line 162, in do
    return getattr(self.registry(), name)(*args, **kwargs)
  File "/Users/andrew.xia/Documents/Github/flasky/venv/lib/python3.6/site-packages/sqlalchemy/orm/session.py", line 1036, in commit
    self.transaction.commit()
  File "/Users/andrew.xia/Documents/Github/flasky/venv/lib/python3.6/site-packages/sqlalchemy/orm/session.py", line 503, in commit
    self._prepare_impl()
  File "/Users/andrew.xia/Documents/Github/flasky/venv/lib/python3.6/site-packages/sqlalchemy/orm/session.py", line 482, in _prepare_impl
    self.session.flush()
  File "/Users/andrew.xia/Documents/Github/flasky/venv/lib/python3.6/site-packages/sqlalchemy/orm/session.py", line 2496, in flush
    self._flush(objects)
  File "/Users/andrew.xia/Documents/Github/flasky/venv/lib/python3.6/site-packages/sqlalchemy/orm/session.py", line 2637, in _flush
    transaction.rollback(_capture_exception=True)
  File "/Users/andrew.xia/Documents/Github/flasky/venv/lib/python3.6/site-packages/sqlalchemy/util/langhelpers.py", line 69, in __exit__
    exc_value, with_traceback=exc_tb,
  File "/Users/andrew.xia/Documents/Github/flasky/venv/lib/python3.6/site-packages/sqlalchemy/util/compat.py", line 178, in raise_
    raise exception
  File "/Users/andrew.xia/Documents/Github/flasky/venv/lib/python3.6/site-packages/sqlalchemy/orm/session.py", line 2597, in _flush
    flush_context.execute()
  File "/Users/andrew.xia/Documents/Github/flasky/venv/lib/python3.6/site-packages/sqlalchemy/orm/unitofwork.py", line 422, in execute
    rec.execute(self)
  File "/Users/andrew.xia/Documents/Github/flasky/venv/lib/python3.6/site-packages/sqlalchemy/orm/unitofwork.py", line 589, in execute
    uow,
  File "/Users/andrew.xia/Documents/Github/flasky/venv/lib/python3.6/site-packages/sqlalchemy/orm/persistence.py", line 236, in save_obj
    update,
  File "/Users/andrew.xia/Documents/Github/flasky/venv/lib/python3.6/site-packages/sqlalchemy/orm/persistence.py", line 995, in _emit_update_statements
    statement, multiparams
  File "/Users/andrew.xia/Documents/Github/flasky/venv/lib/python3.6/site-packages/sqlalchemy/engine/base.py", line 984, in execute
    return meth(self, multiparams, params)
  File "/Users/andrew.xia/Documents/Github/flasky/venv/lib/python3.6/site-packages/sqlalchemy/sql/elements.py", line 293, in _execute_on_connection
    return connection._execute_clauseelement(self, multiparams, params)
  File "/Users/andrew.xia/Documents/Github/flasky/venv/lib/python3.6/site-packages/sqlalchemy/engine/base.py", line 1103, in _execute_clauseelement
    distilled_params,
  File "/Users/andrew.xia/Documents/Github/flasky/venv/lib/python3.6/site-packages/sqlalchemy/engine/base.py", line 1288, in _execute_context
    e, statement, parameters, cursor, context
  File "/Users/andrew.xia/Documents/Github/flasky/venv/lib/python3.6/site-packages/sqlalchemy/engine/base.py", line 1482, in _handle_dbapi_exception
    sqlalchemy_exception, with_traceback=exc_info[2], from_=e
  File "/Users/andrew.xia/Documents/Github/flasky/venv/lib/python3.6/site-packages/sqlalchemy/util/compat.py", line 178, in raise_
    raise exception
  File "/Users/andrew.xia/Documents/Github/flasky/venv/lib/python3.6/site-packages/sqlalchemy/engine/base.py", line 1248, in _execute_context
    cursor, statement, parameters, context
  File "/Users/andrew.xia/Documents/Github/flasky/venv/lib/python3.6/site-packages/sqlalchemy/engine/default.py", line 590, in do_execute
    cursor.execute(statement, parameters)
sqlalchemy.exc.IntegrityError: (sqlite3.IntegrityError) UNIQUE constraint failed: user.username
[SQL: UPDATE user SET username=?, about_me=? WHERE user.id = ?]
[parameters: ('dong', 'dongjohn', 3)]
(Background on this error at: http://sqlalche.me/e/gkpj)
2020-04-24 18:02:23,191 INFO: Microblog startup [in /Users/andrew.xia/Documents/Github/flasky/app/__init__.py:45]
2020-04-24 18:20:54,329 INFO: Microblog startup [in /Users/andrew.xia/Documents/Github/flasky/app/__init__.py:45]
2020-04-24 18:21:11,739 INFO: Microblog startup [in /Users/andrew.xia/Documents/Github/flasky/app/__init__.py:45]
2020-04-24 18:21:18,785 INFO: Microblog startup [in /Users/andrew.xia/Documents/Github/flasky/app/__init__.py:45]
2020-04-24 18:28:34,421 INFO: Microblog startup [in /Users/andrew.xia/Documents/Github/flasky/app/__init__.py:45]
2020-04-25 13:50:23,347 INFO: Microblog startup [in /Users/andrew.xia/Documents/Github/flasky/app/__init__.py:45]
2020-04-25 13:51:04,273 INFO: Microblog startup [in /Users/andrew.xia/Documents/Github/flasky/app/__init__.py:45]
2020-04-25 13:51:13,241 INFO: Microblog startup [in /Users/andrew.xia/Documents/Github/flasky/app/__init__.py:45]
2020-04-25 14:08:20,193 INFO: Microblog startup [in /Users/andrew.xia/Documents/Github/flasky/app/__init__.py:45]
2020-04-25 14:13:00,717 INFO: Microblog startup [in /Users/andrew.xia/Documents/Github/flasky/app/__init__.py:45]
2020-04-25 14:22:40,149 INFO: Microblog startup [in /Users/andrew.xia/Documents/Github/flasky/app/__init__.py:45]
2020-04-25 14:22:52,515 ERROR: Exception on /followed_posts/dongjohn [GET] [in /Users/andrew.xia/Documents/Github/flasky/venv/lib/python3.6/site-packages/flask/app.py:1891]
Traceback (most recent call last):
  File "/Users/andrew.xia/Documents/Github/flasky/venv/lib/python3.6/site-packages/flask/app.py", line 2446, in wsgi_app
    response = self.full_dispatch_request()
  File "/Users/andrew.xia/Documents/Github/flasky/venv/lib/python3.6/site-packages/flask/app.py", line 1951, in full_dispatch_request
    rv = self.handle_user_exception(e)
  File "/Users/andrew.xia/Documents/Github/flasky/venv/lib/python3.6/site-packages/flask/app.py", line 1820, in handle_user_exception
    reraise(exc_type, exc_value, tb)
  File "/Users/andrew.xia/Documents/Github/flasky/venv/lib/python3.6/site-packages/flask/_compat.py", line 39, in reraise
    raise value
  File "/Users/andrew.xia/Documents/Github/flasky/venv/lib/python3.6/site-packages/flask/app.py", line 1949, in full_dispatch_request
    rv = self.dispatch_request()
  File "/Users/andrew.xia/Documents/Github/flasky/venv/lib/python3.6/site-packages/flask/app.py", line 1935, in dispatch_request
    return self.view_functions[rule.endpoint](**req.view_args)
  File "/Users/andrew.xia/Documents/Github/flasky/venv/lib/python3.6/site-packages/flask_login/utils.py", line 272, in decorated_view
    return func(*args, **kwargs)
  File "/Users/andrew.xia/Documents/Github/flasky/app/routes.py", line 37, in followed_posts
    posts = [{'author': p.author.name, 'body': p.body} for p in posts]
  File "/Users/andrew.xia/Documents/Github/flasky/app/routes.py", line 37, in <listcomp>
    posts = [{'author': p.author.name, 'body': p.body} for p in posts]
AttributeError: 'User' object has no attribute 'name'
2020-04-25 14:23:22,564 INFO: Microblog startup [in /Users/andrew.xia/Documents/Github/flasky/app/__init__.py:45]
2020-04-25 14:24:22,008 INFO: Microblog startup [in /Users/andrew.xia/Documents/Github/flasky/app/__init__.py:45]
